Workbook

Sheet programma 3 december
A1: Programma Cebeco MOTIvatiedagen woensdag 3 december 2025
A4: 08.00 - | B4: 08.10 | C4: Welkom | E4: plenair in zaal Molenhoek
A5: 08.15 - | B5: 09.15 | C5: lezing 1 | E5: 46 | F5: =VLOOKUP(E5,'Lezingen 2025'!$A$1:$F$61,2) -> Agrifirm Plenair zaal Molenhoek: Totaal Gewas Aanpak
A7: 09.15 - | B7: 09.30 | C7: pauze
E8: Gouden Leeuw 2 | G8: Akkerbouw | I8: Gouden Leeuw 3 | K8: Akkerbouw | M8: Kinderdijk | O8: Akkerbouw | Q8: Princeville | S8: Akkerbouw | U8: Haagse Schouw | W8: Akkerbouw | Y8: De Witte | AA8: Akkerbouw
A9: 09.30 - | B9: 10.15 | C9: lezing 2 | E9: 23 | F9: =VLOOKUP(E9,'Lezingen 2025'!$A$1:$F$61,2) -> CropLife | G9: =VLOOKUP(E9,'Lezingen 2025'!$A$1:$F$61,3) -> Eric Kiers | I9: 4 | J9: =VLOOKUP(I9,'Lezingen 2025'!$A$1:$F$61,2) -> BASF | K9: =VLOOKUP(I9,'Lezingen 2025'!$A$1:$F$61,3) -> Bert Westhoff | M9: 51 | N9: =VLOOKUP(M9,'Lezingen 2025'!$A$1:$F$61,2) -> Agrifirm & UPL | O9: =VLOOKUP(M9,'Lezingen 2025'!$A$1:$F$61,3) -> Joris Roskam & Marcel van Doorne | Q9: 25 | R9: =VLOOKUP(Q9,'Lezingen 2025'!$A$1:$F$61,2) -> FMC | S9: =VLOOKUP(Q9,'Lezingen 2025'!$A$1:$F$61,3) -> Anton Bom | U9: 38 | V9: =VLOOKUP(U9,'Lezingen 2025'!$A$1:$F$61,2) -> Pireco | W9: =VLOOKUP(U9,'Lezingen 2025'!$A$1:$F$61,3) -> Weimar de Ridder | Y9: 47 | Z9: =VLOOKUP(Y9,'Lezingen 2025'!$A$1:$F$61,2) -> Agrifirm | AA9: =VLOOKUP(Y9,'Lezingen 2025'!$A$1:$F$61,3) -> Fokko Prins
F10: =VLOOKUP(E9,'Lezingen 2025'!$A$1:$F$61,4) -> algemeen | G10: =VLOOKUP(E9,'Lezingen 2025'!$A$1:$F$61,5) -> GBM en PFAS, hoe zit het? | J10: =VLOOKUP(I9,'Lezingen 2025'!$A$1:$F$61,4) -> aardappel | K10: =VLOOKUP(I9,'Lezingen 2025'!$A$1:$F$61,5) -> Nieuwe phytophthora strategie met Zampro Plus | N10: =VLOOKUP(M9,'Lezingen 2025'!$A$1:$F$61,4) -> bieten | O10: =VLOOKUP(M9,'Lezingen 2025'!$A$1:$F$61,5) -> GEWASKRACHT REEF technische introductie | R10: =VLOOKUP(Q9,'Lezingen 2025'!$A$1:$F$61,4) -> bieten | S10: =VLOOKUP(Q9,'Lezingen 2025'!$A$1:$F$61,5) -> Actualiteiten in bieten, onkruid en insectenbestrijding | V10: =VLOOKUP(U9,'Lezingen 2025'!$A$1:$F$61,4) -> uien | W10: =VLOOKUP(U9,'Lezingen 2025'!$A$1:$F$61,5) -> Toekomstige weerbare uienteelt | Z10: =VLOOKUP(Y9,'Lezingen 2025'!$A$1:$F$61,4) -> algemeen | AA10: =VLOOKUP(Y9,'Lezingen 2025'!$A$1:$F$61,5) -> Concepten ontwikkeling en uitrol
A11: 10.15 - | B11: 10.30 | C11: pauze
A12: 10.30 - | B12: 11.15 | C12: lezing 3 | E12: 2 | F12: =VLOOKUP(E12,'Lezingen 2025'!$A$1:$F$61,2) -> ADAMA | G12: =VLOOKUP(E12,'Lezingen 2025'!$A$1:$F$61,3) -> Hanko Blok | I12: 4 | J12: =VLOOKUP(I12,'Lezingen 2025'!$A$1:$F$61,2) -> BASF | K12: =VLOOKUP(I12,'Lezingen 2025'!$A$1:$F$61,3) -> Bert Westhoff | M12: 51 | N12: =VLOOKUP(M12,'Lezingen 2025'!$A$1:$F$61,2) -> Agrifirm & UPL | O12: =VLOOKUP(M12,'Lezingen 2025'!$A$1:$F$61,3) -> Joris Roskam & Marcel van Doorne | Q12: 26 | R12: =VLOOKUP(Q12,'Lezingen 2025'!$A$1:$F$61,2) -> FMC | S12: =VLOOKUP(Q12,'Lezingen 2025'!$A$1:$F$61,3) -> Anton Bom | U12: 38 | V12: =VLOOKUP(U12,'Lezingen 2025'!$A$1:$F$61,2) -> Pireco | W12: =VLOOKUP(U12,'Lezingen 2025'!$A$1:$F$61,3) -> Weimar de Ridder | Y12: 47 | Z12: =VLOOKUP(Y12,'Lezingen 2025'!$A$1:$F$61,2) -> Agrifirm | AA12: =VLOOKUP(Y12,'Lezingen 2025'!$A$1:$F$61,3) -> Fokko Prins
F13: =VLOOKUP(E12,'Lezingen 2025'!$A$1:$F$61,4) -> bieten | G13: =VLOOKUP(E12,'Lezingen 2025'!$A$1:$F$61,5) -> Verdieping resistentieproblema- tiek bietenteelt | J13: =VLOOKUP(I12,'Lezingen 2025'!$A$1:$F$61,4) -> aardappel | K13: =VLOOKUP(I12,'Lezingen 2025'!$A$1:$F$61,5) -> Nieuwe phytophthora strategie met Zampro Plus | N13: =VLOOKUP(M12,'Lezingen 2025'!$A$1:$F$61,4) -> bieten | O13: =VLOOKUP(M12,'Lezingen 2025'!$A$1:$F$61,5) -> GEWASKRACHT REEF technische introductie | R13: =VLOOKUP(Q12,'Lezingen 2025'!$A$1:$F$61,4) -> aardappel | S13: =VLOOKUP(Q12,'Lezingen 2025'!$A$1:$F$61,5) -> Actualiteiten aardappel, herbiciden, fungiciden, loofdoding | V13: =VLOOKUP(U12,'Lezingen 2025'!$A$1:$F$61,4) -> uien | W13: =VLOOKUP(U12,'Lezingen 2025'!$A$1:$F$61,5) -> Toekomstige weerbare uienteelt | Z13: =VLOOKUP(Y12,'Lezingen 2025'!$A$1:$F$61,4) -> algemeen | AA13: =VLOOKUP(Y12,'Lezingen 2025'!$A$1:$F$61,5) -> Concepten ontwikkeling en uitrol
A14: 11.15 - | B14: 11.30 | C14: pauze
A15: 11.30 - | B15: 12.15 | C15: lezing 4 | E15: 23 | F15: =VLOOKUP(E15,'Lezingen 2025'!$A$1:$F$61,2) -> CropLife | G15: =VLOOKUP(E15,'Lezingen 2025'!$A$1:$F$61,3) -> Eric Kiers | I15: 5 | J15: =VLOOKUP(I15,'Lezingen 2025'!$A$1:$F$61,2) -> BASF | K15: =VLOOKUP(I15,'Lezingen 2025'!$A$1:$F$61,3) -> Guus Bergmans | M15: 51 | N15: =VLOOKUP(M15,'Lezingen 2025'!$A$1:$F$61,2) -> Agrifirm & UPL | O15: =VLOOKUP(M15,'Lezingen 2025'!$A$1:$F$61,3) -> Joris Roskam & Marcel van Doorne | Q15: 52 | R15: =VLOOKUP(Q15,'Lezingen 2025'!$A$1:$F$61,2) -> Agrifirm | S15: =VLOOKUP(Q15,'Lezingen 2025'!$A$1:$F$61,3) -> Gewasbescherming in een notedop | U15: 50 | V15: =VLOOKUP(U15,'Lezingen 2025'!$A$1:$F$61,2) -> Agrifirm | W15: =VLOOKUP(U15,'Lezingen 2025'!$A$1:$F$61,3) -> Evert Hofman & Abemec | Y15: 47 | Z15: =VLOOKUP(Y15,'Lezingen 2025'!$A$1:$F$61,2) -> Agrifirm | AA15: =VLOOKUP(Y15,'Lezingen 2025'!$A$1:$F$61,3) -> Fokko Prins
F16: =VLOOKUP(E15,'Lezingen 2025'!$A$1:$F$61,4) -> algemeen | G16: =VLOOKUP(E15,'Lezingen 2025'!$A$1:$F$61,5) -> GBM en PFAS, hoe zit het? | J16: =VLOOKUP(I15,'Lezingen 2025'!$A$1:$F$61,4) -> uien | K16: =VLOOKUP(I15,'Lezingen 2025'!$A$1:$F$61,5) -> Nieuw: Divexo tegen valse meeldauw + uitdagingen onkruidbestrijding | N16: =VLOOKUP(M15,'Lezingen 2025'!$A$1:$F$61,4) -> bieten | O16: =VLOOKUP(M15,'Lezingen 2025'!$A$1:$F$61,5) -> GEWASKRACHT REEF technische introductie | R16: =VLOOKUP(Q15,'Lezingen 2025'!$A$1:$F$61,4) -> algemeen | S16: =VLOOKUP(Q15,'Lezingen 2025'!$A$1:$F$61,5) -> introductie voor Abemec | V16: =VLOOKUP(U15,'Lezingen 2025'!$A$1:$F$61,4) -> algemeen | W16: =VLOOKUP(U15,'Lezingen 2025'!$A$1:$F$61,5) -> Toekomst Techniek toepassing GBM | Z16: =VLOOKUP(Y15,'Lezingen 2025'!$A$1:$F$61,4) -> algemeen | AA16: =VLOOKUP(Y15,'Lezingen 2025'!$A$1:$F$61,5) -> Concepten ontwikkeling en uitrol
A17: 12.15 - | B17: 13.15 | C17: lunch
A18: 13.15 - | B18: 14.00 | C18: lezing 5 | E18: 42 | F18: =VLOOKUP(E18,'Lezingen 2025'!$A$1:$F$61,2) -> Syngenta | G18: =VLOOKUP(E18,'Lezingen 2025'!$A$1:$F$61,3) -> Marnix Gijlers en Steven Dorrestijn | I18: 5 | J18: =VLOOKUP(I18,'Lezingen 2025'!$A$1:$F$61,2) -> BASF | K18: =VLOOKUP(I18,'Lezingen 2025'!$A$1:$F$61,3) -> Guus Bergmans | M18: 7 | N18: =VLOOKUP(M18,'Lezingen 2025'!$A$1:$F$61,2) -> BASF | O18: =VLOOKUP(M18,'Lezingen 2025'!$A$1:$F$61,3) -> Guus Bergmans | Q18: 49 | R18: =VLOOKUP(Q18,'Lezingen 2025'!$A$1:$F$61,2) -> Agrifirm | S18: =VLOOKUP(Q18,'Lezingen 2025'!$A$1:$F$61,3) -> Mark Kersten | U18: 50 | V18: =VLOOKUP(U18,'Lezingen 2025'!$A$1:$F$61,2) -> Agrifirm | W18: =VLOOKUP(U18,'Lezingen 2025'!$A$1:$F$61,3) -> Evert Hofman & Abemec | Y18: 47 | Z18: =VLOOKUP(Y18,'Lezingen 2025'!$A$1:$F$61,2) -> Agrifirm | AA18: =VLOOKUP(Y18,'Lezingen 2025'!$A$1:$F$61,3) -> Fokko Prins
F19: =VLOOKUP(E18,'Lezingen 2025'!$A$1:$F$61,4) -> aardappelen, ui en peen | G19: =VLOOKUP(E18,'Lezingen 2025'!$A$1:$F$61,5) -> Hutspot voor gevorderden | J19: =VLOOKUP(I18,'Lezingen 2025'!$A$1:$F$61,4) -> uien | K19: =VLOOKUP(I18,'Lezingen 2025'!$A$1:$F$61,5) -> Nieuw: Divexo tegen valse meeldauw + uitdagingen onkruidbestrijding | N19: =VLOOKUP(M18,'Lezingen 2025'!$A$1:$F$61,4) -> bieten | O19: =VLOOKUP(M18,'Lezingen 2025'!$A$1:$F$61,5) -> Slimme strategieën in bieten | R19: =VLOOKUP(Q18,'Lezingen 2025'!$A$1:$F$61,4) -> algemeen | S19: =VLOOKUP(Q18,'Lezingen 2025'!$A$1:$F$61,5) -> Goed zaken doen | V19: =VLOOKUP(U18,'Lezingen 2025'!$A$1:$F$61,4) -> algemeen | W19: =VLOOKUP(U18,'Lezingen 2025'!$A$1:$F$61,5) -> Toekomst Techniek toepassing GBM | Z19: =VLOOKUP(Y18,'Lezingen 2025'!$A$1:$F$61,4) -> algemeen | AA19: =VLOOKUP(Y18,'Lezingen 2025'!$A$1:$F$61,5) -> Concepten ontwikkeling en uitrol
A20: 14.00 - | B20: 14.15 | C20: pauze
A21: 14.15 - | B21: 15.00 | C21: lezing 6 | E21: 45 | F21: =VLOOKUP(E21,'Lezingen 2025'!$A$1:$F$61,2) -> WUR | G21: =VLOOKUP(E21,'Lezingen 2025'!$A$1:$F$61,3) -> Geert Kessel | I21: 3 | J21: =VLOOKUP(I21,'Lezingen 2025'!$A$1:$F$61,2) -> BASF | K21: =VLOOKUP(I21,'Lezingen 2025'!$A$1:$F$61,3) -> Bert Westhoff | M21: 1 | N21: =VLOOKUP(M21,'Lezingen 2025'!$A$1:$F$61,2) -> ADAMA | O21: =VLOOKUP(M21,'Lezingen 2025'!$A$1:$F$61,3) -> Kevin de Lange | Q21: 49 | R21: =VLOOKUP(Q21,'Lezingen 2025'!$A$1:$F$61,2) -> Agrifirm | S21: =VLOOKUP(Q21,'Lezingen 2025'!$A$1:$F$61,3) -> Mark Kersten | U21: 50 | V21: =VLOOKUP(U21,'Lezingen 2025'!$A$1:$F$61,2) -> Agrifirm | W21: =VLOOKUP(U21,'Lezingen 2025'!$A$1:$F$61,3) -> Evert Hofman & Abemec | Y21: 41 | Z21: =VLOOKUP(Y21,'Lezingen 2025'!$A$1:$F$61,2) -> Syngenta | AA21: =VLOOKUP(Y21,'Lezingen 2025'!$A$1:$F$61,3) -> Steven Dorrestijn
F22: =VLOOKUP(E21,'Lezingen 2025'!$A$1:$F$61,4) -> aardappel | G22: =VLOOKUP(E21,'Lezingen 2025'!$A$1:$F$61,5) -> Update Phytophthora | J22: =VLOOKUP(I21,'Lezingen 2025'!$A$1:$F$61,4) -> graan | K22: =VLOOKUP(I21,'Lezingen 2025'!$A$1:$F$61,5) -> Luximo; nieuwe dimensie voor sterke grassenbestrijding | N22: =VLOOKUP(M21,'Lezingen 2025'!$A$1:$F$61,4) -> graan | O22: =VLOOKUP(M21,'Lezingen 2025'!$A$1:$F$61,5) -> Actualiteiten en vernieuwingen graanportfolio ADAMA | R22: =VLOOKUP(Q21,'Lezingen 2025'!$A$1:$F$61,4) -> algemeen | S22: =VLOOKUP(Q21,'Lezingen 2025'!$A$1:$F$61,5) -> Goed zaken doen | V22: =VLOOKUP(U21,'Lezingen 2025'!$A$1:$F$61,4) -> algemeen | W22: =VLOOKUP(U21,'Lezingen 2025'!$A$1:$F$61,5) -> Toekomst Techniek toepassing GBM | Z22: =VLOOKUP(Y21,'Lezingen 2025'!$A$1:$F$61,4) -> uien | AA22: =VLOOKUP(Y21,'Lezingen 2025'!$A$1:$F$61,5) -> Waarom vallen de opbrengsten in uien tegen?
A23: 15.00 - | B23: 15.15 | C23: pauze
A24: 15.15 - | B24: 16.00 | C24: lezing 7 | E24: 45 | F24: =VLOOKUP(E24,'Lezingen 2025'!$A$1:$F$61,2) -> WUR | G24: =VLOOKUP(E24,'Lezingen 2025'!$A$1:$F$61,3) -> Geert Kessel | I24: 37 | J24: =VLOOKUP(I24,'Lezingen 2025'!$A$1:$F$61,2) -> Pireco | K24: =VLOOKUP(I24,'Lezingen 2025'!$A$1:$F$61,3) -> Job Simmes | M24: 44 | N24: =VLOOKUP(M24,'Lezingen 2025'!$A$1:$F$61,2) -> UPL | O24: =VLOOKUP(M24,'Lezingen 2025'!$A$1:$F$61,3) -> Marcel van Doorne | Q24: 49 | R24: =VLOOKUP(Q24,'Lezingen 2025'!$A$1:$F$61,2) -> Agrifirm | S24: =VLOOKUP(Q24,'Lezingen 2025'!$A$1:$F$61,3) -> Mark Kersten | U24: 50 | V24: =VLOOKUP(U24,'Lezingen 2025'!$A$1:$F$61,2) -> Agrifirm | W24: =VLOOKUP(U24,'Lezingen 2025'!$A$1:$F$61,3) -> Evert Hofman & Abemec | Y24: 32 | Z24: =VLOOKUP(Y24,'Lezingen 2025'!$A$1:$F$61,2) -> LALLEMAND | AA24: =VLOOKUP(Y24,'Lezingen 2025'!$A$1:$F$61,3) -> Lucie Martin & Alexandra Aldeia
F25: =VLOOKUP(E24,'Lezingen 2025'!$A$1:$F$61,4) -> aardappel | G25: =VLOOKUP(E24,'Lezingen 2025'!$A$1:$F$61,5) -> Update Phytophthora | J25: =VLOOKUP(I24,'Lezingen 2025'!$A$1:$F$61,4) -> aardappel | K25: =VLOOKUP(I24,'Lezingen 2025'!$A$1:$F$61,5) -> Betere kwaliteit knollen, gezonder loof - hogere opbrengst | N25: =VLOOKUP(M24,'Lezingen 2025'!$A$1:$F$61,4) -> aardappel | O25: =VLOOKUP(M24,'Lezingen 2025'!$A$1:$F$61,5) -> Bewaring na ROYAL MH en 5 jaar ervaring met ARGOS | R25: =VLOOKUP(Q24,'Lezingen 2025'!$A$1:$F$61,4) -> algemeen | S25: =VLOOKUP(Q24,'Lezingen 2025'!$A$1:$F$61,5) -> Goed zaken doen | V25: =VLOOKUP(U24,'Lezingen 2025'!$A$1:$F$61,4) -> algemeen | W25: =VLOOKUP(U24,'Lezingen 2025'!$A$1:$F$61,5) -> Toekomst Techniek toepassing GBM | Z25: =VLOOKUP(Y24,'Lezingen 2025'!$A$1:$F$61,4) -> uien | AA25: =VLOOKUP(Y24,'Lezingen 2025'!$A$1:$F$61,5) -> LALGUARD M52 OD: a sustainable & efficient alternative
A26: 16.00 - | B26: 16.15 | C26: pauze
A27: 16.15 - | B27: 17.00 | C27: lezing 8 | E27: 45 | F27: =VLOOKUP(E27,'Lezingen 2025'!$A$1:$F$61,2) -> WUR | G27: =VLOOKUP(E27,'Lezingen 2025'!$A$1:$F$61,3) -> Geert Kessel | I27: 43 | J27: =VLOOKUP(I27,'Lezingen 2025'!$A$1:$F$61,2) -> Syngenta | K27: =VLOOKUP(I27,'Lezingen 2025'!$A$1:$F$61,3) -> Marnix Gijlers | M27: 51 | N27: =VLOOKUP(M27,'Lezingen 2025'!$A$1:$F$61,2) -> Agrifirm & UPL | O27: =VLOOKUP(M27,'Lezingen 2025'!$A$1:$F$61,3) -> Joris Roskam & Marcel van Doorne | Q27: 49 | R27: =VLOOKUP(Q27,'Lezingen 2025'!$A$1:$F$61,2) -> Agrifirm | S27: =VLOOKUP(Q27,'Lezingen 2025'!$A$1:$F$61,3) -> Mark Kersten | U27: 6 | V27: =VLOOKUP(U27,'Lezingen 2025'!$A$1:$F$61,2) -> BASF | W27: =VLOOKUP(U27,'Lezingen 2025'!$A$1:$F$61,3) -> Guus Bergmans | Y27: 33 | Z27: =VLOOKUP(Y27,'Lezingen 2025'!$A$1:$F$61,2) -> LALLEMAND | AA27: =VLOOKUP(Y27,'Lezingen 2025'!$A$1:$F$61,3) -> Lucie Martin & Alexandra Aldeia
F28: =VLOOKUP(E27,'Lezingen 2025'!$A$1:$F$61,4) -> aardappel | G28: =VLOOKUP(E27,'Lezingen 2025'!$A$1:$F$61,5) -> Update Phytophthora | J28: =VLOOKUP(I27,'Lezingen 2025'!$A$1:$F$61,4) -> aardappelen | K28: =VLOOKUP(I27,'Lezingen 2025'!$A$1:$F$61,5) -> Geen horde te hoog voor Phytophthora; Fight Blight Right | N28: =VLOOKUP(M27,'Lezingen 2025'!$A$1:$F$61,4) -> bieten | O28: =VLOOKUP(M27,'Lezingen 2025'!$A$1:$F$61,5) -> GEWASKRACHT REEF technische introductie | R28: =VLOOKUP(Q27,'Lezingen 2025'!$A$1:$F$61,4) -> algemeen | S28: =VLOOKUP(Q27,'Lezingen 2025'!$A$1:$F$61,5) -> Goed zaken doen | V28: =VLOOKUP(U27,'Lezingen 2025'!$A$1:$F$61,4) -> aardappel | W28: =VLOOKUP(U27,'Lezingen 2025'!$A$1:$F$61,5) -> Sterke start aardappel: nieuwe ervaringen Basagran, Allstar | Z28: =VLOOKUP(Y27,'Lezingen 2025'!$A$1:$F$61,4) -> algemeen | AA28: =VLOOKUP(Y27,'Lezingen 2025'!$A$1:$F$61,5) -> New tool for ICM: LALSTOP G46 WG for soil-borne diseases
A29: 17.00 - | B29: 17.45 | C29: aperitief
A30: 17.45 - | B30: 19.15 | C30: dinerbuffet
A31: 20.00 - | B31: 21.15 | C31: avondprogramma in Molenhoek
A32: 21.15 - | B32: 01.00 | C32: bar businessfoyer open

Sheet programma 4 december
A1: Programma Cebeco MOTIvatiedagen donderdag 4 december 2025
A3: 07.00 u - | B3: 08.00 u | C3: ontbijt
A4: 08.00 u - | B4: 08.10 u | C4: plenaire start in zaal Molenhoek
A5: 08.10 u - | B5: 08.15 u | C5: deelnemers naar de desbetreffende zaal
A6: tijdstip | C6: programma | E6: Gouden Leeuw 2 | G6: Akkerbouw | I6: Gouden Leeuw 3 | K6: Akkerbouw | M6: Princeville | O6: Akkerbouw | Q6: Haagse Schouw | S6: Akkerbouw | U6: De Witte | W6: Akkerbouw
A7: 08.15 - | B7: 09.15 | C7: lezing 1 | E7: 48 | F7: =VLOOKUP(E7,'Lezingen 2025'!$A$1:$F$61,2) -> Agrifirm | G7: =VLOOKUP(E7,'Lezingen 2025'!$A$1:$F$61,3) -> Malda & Brakemeier | I7: 17 | J7: =VLOOKUP(I7,'Lezingen 2025'!$A$1:$F$61,2) -> Corteva | K7: =VLOOKUP(I7,'Lezingen 2025'!$A$1:$F$61,3) -> Allard /Joris / Rien | M7: 40 | N7: =VLOOKUP(M7,'Lezingen 2025'!$A$1:$F$61,2) -> Rovensa next | O7: =VLOOKUP(M7,'Lezingen 2025'!$A$1:$F$61,3) -> Loïc / Erwin | Q7: 27 | R7: =VLOOKUP(Q7,'Lezingen 2025'!$A$1:$F$61,2) -> IRS | S7: =VLOOKUP(Q7,'Lezingen 2025'!$A$1:$F$61,3) -> Elma Raaijmakers | U7: 53 | V7: =VLOOKUP(U7,'Lezingen 2025'!$A$1:$F$61,2) -> Restrain* | W7: =VLOOKUP(U7,'Lezingen 2025'!$A$1:$F$61,3) -> i.o.
F8: =VLOOKUP(E7,'Lezingen 2025'!$A$1:$F$61,4) -> algemeen | G8: =VLOOKUP(E7,'Lezingen 2025'!$A$1:$F$61,5) -> Biostimulanten noodzaak en nut | J8: =VLOOKUP(I7,'Lezingen 2025'!$A$1:$F$61,4) -> wintertarwe | K8: =VLOOKUP(I7,'Lezingen 2025'!$A$1:$F$61,5) -> Fencade + Renitar, een stap vooruit in de voorjaars onkruidbestrijding wintertarwe | N8: =VLOOKUP(M7,'Lezingen 2025'!$A$1:$F$61,4) -> akkerbouw | O8: =VLOOKUP(M7,'Lezingen 2025'!$A$1:$F$61,5) -> Transformer bij v.o. herbiciden + meerwaarde- Humifirst. Introductie Biimore biostimulant | R8: =VLOOKUP(Q7,'Lezingen 2025'!$A$1:$F$61,4) -> algemeen | S8: =VLOOKUP(Q7,'Lezingen 2025'!$A$1:$F$61,5) -> SBR en RTD/Stolbur oplossen via bouwplanbrede aanpak | V8: =VLOOKUP(U7,'Lezingen 2025'!$A$1:$F$61,4) -> algemeen | W8: =VLOOKUP(U7,'Lezingen 2025'!$A$1:$F$61,5) -> Introductie Restrain
A9: 09.15 - | B9: 09.30 | C9: pauze
A10: 09.30 - | B10: 10.15 | C10: lezing 2 | E10: 48 | F10: =VLOOKUP(E10,'Lezingen 2025'!$A$1:$F$61,2) -> Agrifirm | G10: =VLOOKUP(E10,'Lezingen 2025'!$A$1:$F$61,3) -> Malda & Brakemeier | I10: 18 | J10: =VLOOKUP(I10,'Lezingen 2025'!$A$1:$F$61,2) -> Corteva | K10: =VLOOKUP(I10,'Lezingen 2025'!$A$1:$F$61,3) -> Allard /Joris / Rien | M10: 14 | N10: =VLOOKUP(M10,'Lezingen 2025'!$A$1:$F$61,2) -> Bayer | O10: =VLOOKUP(M10,'Lezingen 2025'!$A$1:$F$61,3) -> Christy van Beek | Q10: 27 | R10: =VLOOKUP(Q10,'Lezingen 2025'!$A$1:$F$61,2) -> IRS | S10: =VLOOKUP(Q10,'Lezingen 2025'!$A$1:$F$61,3) -> Elma Raaijmakers | U10: 53 | V10: =VLOOKUP(U10,'Lezingen 2025'!$A$1:$F$61,2) -> Restrain* | W10: =VLOOKUP(U10,'Lezingen 2025'!$A$1:$F$61,3) -> i.o.
F11: =VLOOKUP(E10,'Lezingen 2025'!$A$1:$F$61,4) -> algemeen | G11: =VLOOKUP(E10,'Lezingen 2025'!$A$1:$F$61,5) -> Biostimulanten noodzaak en nut | J11: =VLOOKUP(I10,'Lezingen 2025'!$A$1:$F$61,4) -> aardappel | K11: =VLOOKUP(I10,'Lezingen 2025'!$A$1:$F$61,5) -> Titus mogelijkheden in het post-Sencor tijdperk + Resultaten demo-proeven 2025 phytophthora bestrijding. | N11: =VLOOKUP(M10,'Lezingen 2025'!$A$1:$F$61,4) -> algemeen | O11: introductie voor Abemec | R11: =VLOOKUP(Q10,'Lezingen 2025'!$A$1:$F$61,4) -> algemeen | S11: =VLOOKUP(Q10,'Lezingen 2025'!$A$1:$F$61,5) -> SBR en RTD/Stolbur oplossen via bouwplanbrede aanpak | V11: =VLOOKUP(U10,'Lezingen 2025'!$A$1:$F$61,4) -> algemeen | W11: =VLOOKUP(U10,'Lezingen 2025'!$A$1:$F$61,5) -> Introductie Restrain
A12: 10.15 - | B12: 10.30 | C12: pauze
A13: 10.30 - | B13: 11.15 | C13: lezing 3 | E13: 48 | F13: =VLOOKUP(E13,'Lezingen 2025'!$A$1:$F$61,2) -> Agrifirm | G13: =VLOOKUP(E13,'Lezingen 2025'!$A$1:$F$61,3) -> Malda & Brakemeier | I13: 19 | J13: =VLOOKUP(I13,'Lezingen 2025'!$A$1:$F$61,2) -> Corteva | K13: =VLOOKUP(I13,'Lezingen 2025'!$A$1:$F$61,3) -> Allard /Joris / Rien | M13: 35 | N13: =VLOOKUP(M13,'Lezingen 2025'!$A$1:$F$61,2) -> Nufarm | O13: =VLOOKUP(M13,'Lezingen 2025'!$A$1:$F$61,3) -> Tjeerd Peeters | Q13: 27 | R13: =VLOOKUP(Q13,'Lezingen 2025'!$A$1:$F$61,2) -> IRS | S13: =VLOOKUP(Q13,'Lezingen 2025'!$A$1:$F$61,3) -> Elma Raaijmakers | U13: 10 | V13: =VLOOKUP(U13,'Lezingen 2025'!$A$1:$F$61,2) -> Bayer | W13: =VLOOKUP(U13,'Lezingen 2025'!$A$1:$F$61,3) -> Stefan / Simon / Sander
F14: =VLOOKUP(E13,'Lezingen 2025'!$A$1:$F$61,4) -> algemeen | G14: =VLOOKUP(E13,'Lezingen 2025'!$A$1:$F$61,5) -> Biostimulanten noodzaak en nut | J14: =VLOOKUP(I13,'Lezingen 2025'!$A$1:$F$61,4) -> bieten | K14: =VLOOKUP(I13,'Lezingen 2025'!$A$1:$F$61,5) -> Wat zijn de mogelijkheden met Lontrel en Rinpode (verwacht voor seizoen 2027) | N14: =VLOOKUP(M13,'Lezingen 2025'!$A$1:$F$61,4) -> uien, aardappel | O14: =VLOOKUP(M13,'Lezingen 2025'!$A$1:$F$61,5) -> Trips- en luisbestrijding met NeemAzal-T/S in buitenteelten. Effectief en biologisch! | R14: =VLOOKUP(Q13,'Lezingen 2025'!$A$1:$F$61,4) -> algemeen | S14: =VLOOKUP(Q13,'Lezingen 2025'!$A$1:$F$61,5) -> SBR en RTD/Stolbur oplossen via bouwplanbrede aanpak | V14: =VLOOKUP(U13,'Lezingen 2025'!$A$1:$F$61,4) -> bieten | W14: =VLOOKUP(U13,'Lezingen 2025'!$A$1:$F$61,5) -> Update Conviso + mogelijkheden in 2026 met Buteo Start en Sivanto op luis en cicaden?
A15: 11.15 - | B15: 11.30 | C15: pauze
A16: 11.30 - | B16: 12.15 | C16: lezing 4 | E16: 48 | F16: =VLOOKUP(E16,'Lezingen 2025'!$A$1:$F$61,2) -> Agrifirm | G16: =VLOOKUP(E16,'Lezingen 2025'!$A$1:$F$61,3) -> Malda & Brakemeier | I16: 20 | J16: =VLOOKUP(I16,'Lezingen 2025'!$A$1:$F$61,2) -> Corteva | K16: =VLOOKUP(I16,'Lezingen 2025'!$A$1:$F$61,3) -> Ruud van de Sande | M16: 14 | N16: =VLOOKUP(M16,'Lezingen 2025'!$A$1:$F$61,2) -> Bayer | O16: =VLOOKUP(M16,'Lezingen 2025'!$A$1:$F$61,3) -> Christy van Beek | Q16: 29 | R16: =VLOOKUP(Q16,'Lezingen 2025'!$A$1:$F$61,2) -> Koppert | S16: =VLOOKUP(Q16,'Lezingen 2025'!$A$1:$F$61,3) -> Koppert | U16: 10 | V16: =VLOOKUP(U16,'Lezingen 2025'!$A$1:$F$61,2) -> Bayer | W16: =VLOOKUP(U16,'Lezingen 2025'!$A$1:$F$61,3) -> Stefan / Simon / Sander
F17: =VLOOKUP(E16,'Lezingen 2025'!$A$1:$F$61,4) -> algemeen | G17: =VLOOKUP(E16,'Lezingen 2025'!$A$1:$F$61,5) -> Biostimulanten noodzaak en nut | J17: =VLOOKUP(I16,'Lezingen 2025'!$A$1:$F$61,4) -> uien | K17: =VLOOKUP(I16,'Lezingen 2025'!$A$1:$F$61,5) -> De puntjes op de ui voor seizoen 2026. | N17: =VLOOKUP(M16,'Lezingen 2025'!$A$1:$F$61,4) -> algemeen | O17: =VLOOKUP(M16,'Lezingen 2025'!$A$1:$F$61,5) -> Staat het water ons nader aan de lippen? | R17: =VLOOKUP(Q16,'Lezingen 2025'!$A$1:$F$61,4) -> algemeen | S17: =VLOOKUP(Q16,'Lezingen 2025'!$A$1:$F$61,5) -> Trianum: Biologisch fungicide tegen bodemziekten - Het alternatief voor een smaller fungiciden pakket - | V17: =VLOOKUP(U16,'Lezingen 2025'!$A$1:$F$61,4) -> bieten | W17: =VLOOKUP(U16,'Lezingen 2025'!$A$1:$F$61,5) -> Update Conviso + mogelijkheden in 2026 met Buteo Start en Sivanto op luis en cicaden?
A18: 12.15 - | B18: 13.15 | C18: lunch
A19: 13.15 - | B19: 14.00 | C19: lezing 5 | E19: 28 | F19: =VLOOKUP(E19,'Lezingen 2025'!$A$1:$F$61,2) -> IRS | G19: =VLOOKUP(E19,'Lezingen 2025'!$A$1:$F$61,3) -> Sjef van der Heijden | I19: 20 | J19: =VLOOKUP(I19,'Lezingen 2025'!$A$1:$F$61,2) -> Corteva | K19: =VLOOKUP(I19,'Lezingen 2025'!$A$1:$F$61,3) -> Ruud van de Sande | M19: 15 | N19: =VLOOKUP(M19,'Lezingen 2025'!$A$1:$F$61,2) -> Certis Belchim | O19: =VLOOKUP(M19,'Lezingen 2025'!$A$1:$F$61,3) -> Fokke Smit & Tom van Driessen | Q19: 30 | R19: =VLOOKUP(Q19,'Lezingen 2025'!$A$1:$F$61,2) -> Koppert | S19: =VLOOKUP(Q19,'Lezingen 2025'!$A$1:$F$61,3) -> Koppert | U19: 12 | V19: =VLOOKUP(U19,'Lezingen 2025'!$A$1:$F$61,2) -> Bayer | W19: =VLOOKUP(U19,'Lezingen 2025'!$A$1:$F$61,3) -> Simon/Sander
F20: =VLOOKUP(E19,'Lezingen 2025'!$A$1:$F$61,4) -> algemeen | G20: =VLOOKUP(E19,'Lezingen 2025'!$A$1:$F$61,5) -> ICM aanpak resistente onkruiden op bouwplan niveau | J20: =VLOOKUP(I19,'Lezingen 2025'!$A$1:$F$61,4) -> uien | K20: =VLOOKUP(I19,'Lezingen 2025'!$A$1:$F$61,5) -> De puntjes op de ui voor seizoen 2026. | N20: =VLOOKUP(M19,'Lezingen 2025'!$A$1:$F$61,4) -> aardappel | O20: =VLOOKUP(M19,'Lezingen 2025'!$A$1:$F$61,5) -> Wandel met ons mee over het Pieperpad | R20: =VLOOKUP(Q19,'Lezingen 2025'!$A$1:$F$61,4) -> algemeen | S20: =VLOOKUP(Q19,'Lezingen 2025'!$A$1:$F$61,5) -> Slimme nematoden: Effectieve oplossingen tegen insectenplagen | V20: =VLOOKUP(U19,'Lezingen 2025'!$A$1:$F$61,4) -> aardappel | W20: =VLOOKUP(U19,'Lezingen 2025'!$A$1:$F$61,5) -> It's all about potatoes, aardappels en nog eens aardappels
A21: 14.00 - | B21: 14.15 | C21: pauze
A22: 14.15 - | B22: 15.00 | C22: lezing 6 | E22: 22 | F22: =VLOOKUP(E22,'Lezingen 2025'!$A$1:$F$61,2) -> Corteva | G22: =VLOOKUP(E22,'Lezingen 2025'!$A$1:$F$61,3) -> Ruud van de Sande | I22: 39 | J22: =VLOOKUP(I22,'Lezingen 2025'!$A$1:$F$61,2) -> PLV Belgie | K22: =VLOOKUP(I22,'Lezingen 2025'!$A$1:$F$61,3) -> Shana Clercx | M22: 15 | N22: =VLOOKUP(M22,'Lezingen 2025'!$A$1:$F$61,2) -> Certis Belchim | O22: =VLOOKUP(M22,'Lezingen 2025'!$A$1:$F$61,3) -> Fokke Smit & Tom van Driessen | Q22: 30 | R22: =VLOOKUP(Q22,'Lezingen 2025'!$A$1:$F$61,2) -> Koppert | S22: =VLOOKUP(Q22,'Lezingen 2025'!$A$1:$F$61,3) -> Koppert | U22: 12 | V22: =VLOOKUP(U22,'Lezingen 2025'!$A$1:$F$61,2) -> Bayer | W22: =VLOOKUP(U22,'Lezingen 2025'!$A$1:$F$61,3) -> Simon/Sander
F23: =VLOOKUP(E22,'Lezingen 2025'!$A$1:$F$61,4) -> akkerbouw | G23: =VLOOKUP(E22,'Lezingen 2025'!$A$1:$F$61,5) -> Hoe kunnen we planthormonen beinvloeden met biostimulanten | J23: =VLOOKUP(I22,'Lezingen 2025'!$A$1:$F$61,4) -> algemeen | K23: =VLOOKUP(I22,'Lezingen 2025'!$A$1:$F$61,5) -> Knolcyperus | N23: =VLOOKUP(M22,'Lezingen 2025'!$A$1:$F$61,4) -> aardappel | O23: =VLOOKUP(M22,'Lezingen 2025'!$A$1:$F$61,5) -> Wandel met ons mee over het Pieperpad | R23: =VLOOKUP(Q22,'Lezingen 2025'!$A$1:$F$61,4) -> algemeen | S23: =VLOOKUP(Q22,'Lezingen 2025'!$A$1:$F$61,5) -> Slimme nematoden: Effectieve oplossingen tegen insectenplagen | V23: =VLOOKUP(U22,'Lezingen 2025'!$A$1:$F$61,4) -> aardappel | W23: =VLOOKUP(U22,'Lezingen 2025'!$A$1:$F$61,5) -> It's all about potatoes, aardappels en nog eens aardappels
A24: 15.00 - | B24: 15.15 | C24: pauze
A25: 15.15 - | B25: 16.00 | C25: lezing 7 | E25: 11 | F25: =VLOOKUP(E25,'Lezingen 2025'!$A$1:$F$61,2) -> Bayer | G25: =VLOOKUP(E25,'Lezingen 2025'!$A$1:$F$61,3) -> Stefan van Heist | I25: 34 | J25: =VLOOKUP(I25,'Lezingen 2025'!$A$1:$F$61,2) -> Naturim | K25: =VLOOKUP(I25,'Lezingen 2025'!$A$1:$F$61,3) -> Sander Bernaerts | M25: 16 | N25: =VLOOKUP(M25,'Lezingen 2025'!$A$1:$F$61,2) -> Certis Belchim | O25: =VLOOKUP(M25,'Lezingen 2025'!$A$1:$F$61,3) -> Maarten van der Marel & Fokke Smit | Q25: 36 | R25: =VLOOKUP(Q25,'Lezingen 2025'!$A$1:$F$61,2) -> Nufarm + Geersing PS | S25: =VLOOKUP(Q25,'Lezingen 2025'!$A$1:$F$61,3) -> Ronny Traas & Jan-Eric Geersing | U25: 31 | V25: =VLOOKUP(U25,'Lezingen 2025'!$A$1:$F$61,2) -> Koppert | W25: =VLOOKUP(U25,'Lezingen 2025'!$A$1:$F$61,3) -> Koppert
F26: =VLOOKUP(E25,'Lezingen 2025'!$A$1:$F$61,4) -> uien | G26: =VLOOKUP(E25,'Lezingen 2025'!$A$1:$F$61,5) -> Aliette nieuw in de (kleine) uien, Serenade update uienbreed | J26: =VLOOKUP(I25,'Lezingen 2025'!$A$1:$F$61,4) -> algemeen | K26: =VLOOKUP(I25,'Lezingen 2025'!$A$1:$F$61,5) -> Regeneratieve landbouw, wat kun jij ermee? | N26: =VLOOKUP(M25,'Lezingen 2025'!$A$1:$F$61,4) -> uien | O26: =VLOOKUP(M25,'Lezingen 2025'!$A$1:$F$61,5) -> Wandel met ons mee over het alternatieve pieperpad | R26: =VLOOKUP(Q25,'Lezingen 2025'!$A$1:$F$61,4) -> aardappel, suikerbiet | S26: =VLOOKUP(Q25,'Lezingen 2025'!$A$1:$F$61,5) -> Robuuste rassen en Nuxine: Van proefveld naar toekomst. | V26: =VLOOKUP(U25,'Lezingen 2025'!$A$1:$F$61,4) -> algemeen | W26: =VLOOKUP(U25,'Lezingen 2025'!$A$1:$F$61,5) -> De kracht van natuurlijke vijanden en bankerplanten
A27: 16.00 - | B27: 16.15 | C27: pauze
A28: 16.15 - | B28: 17.00 | C28: lezing 8 | E28: 24 | F28: =VLOOKUP(E28,'Lezingen 2025'!$A$1:$F$61,2) -> ECOstyle | G28: =VLOOKUP(E28,'Lezingen 2025'!$A$1:$F$61,3) -> Aukje Veldstra | I28: 34 | J28: =VLOOKUP(I28,'Lezingen 2025'!$A$1:$F$61,2) -> Naturim | K28: =VLOOKUP(I28,'Lezingen 2025'!$A$1:$F$61,3) -> Sander Bernaerts | M28: 16 | N28: =VLOOKUP(M28,'Lezingen 2025'!$A$1:$F$61,2) -> Certis Belchim | O28: =VLOOKUP(M28,'Lezingen 2025'!$A$1:$F$61,3) -> Maarten van der Marel & Fokke Smit | Q28: 36 | R28: =VLOOKUP(Q28,'Lezingen 2025'!$A$1:$F$61,2) -> Nufarm + Geersing PS | S28: =VLOOKUP(Q28,'Lezingen 2025'!$A$1:$F$61,3) -> Ronny Traas & Jan-Eric Geersing | U28: 31 | V28: =VLOOKUP(U28,'Lezingen 2025'!$A$1:$F$61,2) -> Koppert | W28: =VLOOKUP(U28,'Lezingen 2025'!$A$1:$F$61,3) -> Koppert
F29: =VLOOKUP(E28,'Lezingen 2025'!$A$1:$F$61,4) -> akkerbouw | G29: =VLOOKUP(E28,'Lezingen 2025'!$A$1:$F$61,5) -> “De kracht van micro-organismen: wetenschap als basis voor rendement” | J29: =VLOOKUP(I28,'Lezingen 2025'!$A$1:$F$61,4) -> algemeen | K29: =VLOOKUP(I28,'Lezingen 2025'!$A$1:$F$61,5) -> Regeneratieve landbouw, wat kun jij ermee? | N29: =VLOOKUP(M28,'Lezingen 2025'!$A$1:$F$61,4) -> uien | O29: =VLOOKUP(M28,'Lezingen 2025'!$A$1:$F$61,5) -> Wandel met ons mee over het alternatieve pieperpad | R29: =VLOOKUP(Q28,'Lezingen 2025'!$A$1:$F$61,4) -> aardappel, suikerbiet | S29: =VLOOKUP(Q28,'Lezingen 2025'!$A$1:$F$61,5) -> Robuuste rassen en Nuxine: Van proefveld naar toekomst. | V29: =VLOOKUP(U28,'Lezingen 2025'!$A$1:$F$61,4) -> algemeen | W29: =VLOOKUP(U28,'Lezingen 2025'!$A$1:$F$61,5) -> De kracht van natuurlijke vijanden en bankerplanten
A30: 17.15 u - | B30: 18.30 u | C30: dinerbuffet
B31: 18.30 u | C31: vertrek

Sheet Lezingen 2025
B1: Bedrijf | C1: Presentator | D1: Gewas | E1: Onderwerp | F1: Extra info | G1: aantal x | H1: #inteken | I1: aantal/zaal | J1: moment
A2: 1 | B2: ADAMA | C2: Kevin de Lange | D2: graan | E2: Actualiteiten en vernieuwingen graanportfolio ADAMA | F2: PGR, Fungicide, septoria monitoring | G2: 1 | H2: 23 | I2: 23 | J2: wo
A3: 2 | B3: ADAMA | C3: Hanko Blok | D3: bieten | E3: Verdieping resistentieproblema- tiek bietenteelt | F3: fungiciden, herbiciden | G3: 1 | H3: 36 | I3: 36 | J3: wo
A4: 3 | B4: BASF | C4: Bert Westhoff | D4: graan | E4: Luximo; nieuwe dimensie voor sterke grassenbestrijding | F4: Grassenbestrijding, duist, straatgras, windhalm, nieuwe chemie in wintertarwe | G4: 1 | H4: 28 | I4: 28 | J4: wo
A5: 4 | B5: BASF | C5: Bert Westhoff | D5: aardappel | E5: Nieuwe phytophthora strategie met Zampro Plus | F5: Nieuwe onderzoeksresultaten met Zampro Plus & Enervin SC . Ervaringen nieuwe strategie met afwisselen en alterneren. Goed resistentiemanagement. Korte introductie Divexo. | G5: 2 | H5: 41 | I5: 21 | J5: wo
A6: =A5+1 -> 5 | B6: BASF | C6: Guus Bergmans | D6: uien | E6: Nieuw: Divexo tegen valse meeldauw + uitdagingen onkruidbestrijding | F6: Divexo; nieuw fungicide tegen valse meeldauw. Stomp 400 SC, Wing P, Basagran: de basis voor een goede onkruidbestrijding. | G6: 2 | H6: 62 | I6: 31 | J6: wo
A7: =A6+1 -> 6 | B7: BASF | C7: Guus Bergmans | D7: aardappel | E7: Sterke start aardappel: nieuwe ervaringen Basagran, Allstar | F7: Actueel onderzoek Basagran; nieuwe ervaringen in aardappel. Sterk op veel breedbladige onkruiden. Nieuw onderzoek Allstar tegen rhizoctonia. | G7: 1 | H7: 22 | I7: 22 | J7: wo
A8: =A7+1 -> 7 | B8: BASF | C8: Guus Bergmans | D8: bieten | E8: Slimme strategieën in bieten | F8: Fungiciden afwisselen voor behoud van effectiviteit. Belanty FL & Diadem. Lastige onkruid bestrijden. Kezuro & Tanaris. | G8: 1 | H8: 17 | I8: 17 | J8: wo
A9: =A8+1 -> 8 | B9: BASF | C9: Bert Westhoff & Guus Bergmans | D9: aardappel | E9: 10 jaar 1,4SIGHT; vroege start loont | F9: Minder bewaarverlies en meer rendement uit de bewaring. Nog vroeger toepassen. | G9: 0 | H9: 9 | I9: 0
A10: =A9+1 -> 9 | B10: BASF | C10: Bert Westhoff | D10: gewas breed | E10: Jouw vragen, onze antwoorden! | F10: Akkerbouw, teeltuitdagingen, registratie, productstewardship, pijplijn ontwikkelingen. Vragen indienen bij BASF minimaal 1 week van te voren. | G10: 0 | H10: 7 | I10: 0
A11: =A10+1 -> 10 | B11: Bayer | C11: Stefan / Simon / Sander | D11: bieten | E11: Update Conviso + mogelijkheden in 2026 met Buteo Start en Sivanto op luis en cicaden? | F11: Conviso, Sivanto, Buteo Start, Bieten, luizen, cicaden | G11: 2 | H11: 44 | I11: 22 | J11: do
A12: =A11+1 -> 11 | B12: Bayer | C12: Stefan van Heist | D12: uien | E12: Aliette nieuw in de (kleine) uien, Serenade update uienbreed | F12: Aliette, Serenade, Rudis, Infinito, Fandango | G12: 1 | H12: 42 | I12: 42 | J12: do
A13: =A12+1 -> 12 | B13: Bayer | C13: Simon/Sander | D13: aardappel | E13: It's all about potatoes, aardappels en nog eens aardappels | F13: Serenade stikstof, Velum Prime, Challenge, Gofor, Sivanto Prime cicaden Stolbur , Infinito, Propulse | G13: 2 | H13: 54 | I13: 27 | J13: do
A14: =A13+1 -> 13 | B14: Bayer | C14: Sander Uwland | D14: mais | E14: Spade nieuw in mais tegen lastige grassen | F14: Spade, Laudis, Monsoon | G14: 0 | H14: 13 | I14: 0 | J14: do
A15: =A14+1 -> 14 | B15: Bayer | C15: Christy van Beek | D15: algemeen | E15: Staat het water ons nader aan de lippen? | F15: Waterkwaliteit, update, duurzaam, wegval van stoffen, uitbreiding normen, CTGB project. | G15: 2 | H15: 54 | I15: 27 | J15: do ochtend
A16: =A15+1 -> 15 | B16: Certis Belchim | C16: Fokke Smit & Tom van Driessen | D16: aardappel | E16: Wandel met ons mee over het Pieperpad | F16: alternaria, phytophthora, onkruid, loofdood, virus, insekten, rhizoctonia, bewaarziekten | G16: 2 | H16: 43 | I16: 22 | J16: do
A17: =A16+1 -> 16 | B17: Certis Belchim | C17: Maarten van der Marel & Fokke Smit | D17: uien | E17: Wandel met ons mee over het alternatieve pieperpad | F17: Trips, valse meeldauw, aaltjes, onkruid, kiemrust | G17: 2 | H17: 50 | I17: 25 | J17: do
A18: =A17+1 -> 17 | B18: Corteva | C18: Allard /Joris / Rien | D18: wintertarwe | E18: Fencade + Renitar, een stap vooruit in de voorjaars onkruidbestrijding wintertarwe | F18: Bestrijding straatgras, duist en breedbladigen + korte update Queen | G18: 1 | H18: 26 | I18: 26 | J18: do
A19: =A18+1 -> 18 | B19: Corteva | C19: Allard /Joris / Rien | D19: aardappel | E19: Titus mogelijkheden in het post-Sencor tijdperk + Resultaten demo-proeven 2025 phytophthora bestrijding. | G19: 1 | H19: 29 | I19: 29 | J19: do
A20: =A19+1 -> 19 | B20: Corteva | C20: Allard /Joris / Rien | D20: bieten | E20: Wat zijn de mogelijkheden met Lontrel en Rinpode (verwacht voor seizoen 2027) | F20: Rinpode, nieuwe werkzame stof voor onkruidbestrijding suikerbieten. Kijkje in de keuken: Queen in suikerbieten vanaf 2028 | G20: 1 | H20: 29 | I20: 29 | J20: do
A21: =A20+1 -> 20 | B21: Corteva | C21: Ruud van de Sande | D21: uien | E21: De puntjes op de ui voor seizoen 2026. | F21: Hoe Tracer zo goed mogelijk inzetten nu middelen zijn weggevallen. Onkruidbestrijding. Valse meeldauwbestrijding | G21: 2 | H21: 59 | I21: 30 | J21: do
A22: =A21+1 -> 21 | B22: Corteva | C22: Allard Jukema | D22: mais en grasland | E22: Nieuwe basis (flex) voor de onkruidbestrijding in mais. Zuinig met uw klaver in grasland. | F22: Mogelijkheden met Basis Flex in mais. Ervaringen Proclova in gras-klaver weiden. | G22: 0 | H22: 9 | I22: 0 | J22: do
A23: =A22+1 -> 22 | B23: Corteva | C23: Ruud van de Sande | D23: akkerbouw | E23: Hoe kunnen we planthormonen beinvloeden met biostimulanten | F23: verdieping en proefresultaten | G23: 1 | H23: 41 | I23: 21 | J23: do
A24: =A23+1 -> 23 | B24: CropLife | C24: Eric Kiers | D24: algemeen | E24: GBM en PFAS, hoe zit het? | F24: Alles rondom PFAS in gewasbescherming. | G24: 2 | H24: 62 | I24: 31 | J24: wo ochtend blok 2 en 4
A25: =A24+1 -> 24 | B25: ECOstyle | C25: Aukje Veldstra | D25: akkerbouw | E25: “De kracht van micro-organismen: wetenschap als basis voor rendement” | F25: Micro-organismen, ProtoPlus Agro, Adviseren microbiologie, Van wetenschap naar praktijk, Combinaties microbiologie producten. | G25: 1 | H25: 31 | I25: 31 | J25: do
A26: =A25+1 -> 25 | B26: FMC | C26: Anton Bom | D26: bieten | E26: Actualiteiten in bieten, onkruid en insectenbestrijding | F26: ervaringen en adviezen: Bietenmot - Coragen NLKUG, onkruidbestrijding - Centium 360 CS en Venzar, 500 S, Luis en bietenvlieg - Exirel (indien weer vrijstelling) | G26: 1 | H26: 17 | I26: 17 | J26: wo
A27: =A26+1 -> 26 | B27: FMC | C27: Anton Bom | D27: aardappel | E27: Actualiteiten aardappel, herbiciden, fungiciden, loofdoding | F27: ervaringen en adviezen: Onkruidbestrijding - Centium 360 CS, Phytophthorabestrijding & Alternariabestrijding - Vendetta, Loofdoding - Spotlight Plus/ Affinity Plus | G27: 1 | H27: 22 | I27: 22 | J27: wo
A28: =A27+1 -> 27 | B28: IRS | C28: Elma Raaijmakers | D28: algemeen | E28: SBR en RTD/Stolbur oplossen via bouwplanbrede aanpak | F28: Een nieuwe dreiging voor veel gewassen in het bouwplan. Wat is de status en hoe pakken we het op? | G28: 3 | H28: 69 | I28: 23 | J28: do ochtend
A29: =A28+1 -> 28 | B29: IRS | C29: Sjef van der Heijden | D29: algemeen | E29: ICM aanpak resistente onkruiden op bouwplan niveau | F29: Resistente onkruiden worden een steeds groter probleem. Een ICM aanpak is nodig! | G29: 1 | H29: 30 | I29: 30 | J29: do ochtend
A30: =A29+1 -> 29 | B30: Koppert | C30: Koppert | D30: algemeen | E30: Trianum: Biologisch fungicide tegen bodemziekten - Het alternatief voor een smaller fungiciden pakket - | F30: Wegvallen fungiciden, Pythium, Fusarium, toepassing van Trianum | G30: 1 | H30: 23 | I30: 23 | J30: do
A31: =A30+1 -> 30 | B31: Koppert | C31: Koppert | D31: algemeen | E31: Slimme nematoden: Effectieve oplossingen tegen insectenplagen | F31: Bonen-, uien- en koolvlieg, emelten, kevers, ritnaalden, insect parasitaire aaltjes | G31: 2 | H31: 47 | I31: 24 | J31: do
... A46: =A45+1 -> 45 | B46: WUR | C46: Geert Kessel | D46: aardappel | E46: Update Phytophthora | F46: update romdom Phytophtora infestans in aardappelen | G46: 3 | H46: 85 | I46: 29 | J46: wo middag
B47: Bedrijf | C47: Presentator | D47: Verplichte lezingen voor iedereen | F47: Extra info
A48: 46 | B48: Agrifirm Plenair zaal Molenhoek: Totaal Gewas Aanpak | G48: 1 | J48: wo ochtend
A49: 47 | B49: Agrifirm | C49: Fokko Prins | D49: algemeen | E49: Concepten ontwikkeling en uitrol | G49: 4 | H49: 108 | I49: 27 | J49: wo
A50: 48 | B50: Agrifirm | C50: Malda & Brakemeier | D50: algemeen | E50: Biostimulanten noodzaak en nut | G50: 4 | H50: 108 | I50: 27 | J50: do
A51: 49 | B51: Agrifirm | C51: Mark Kersten | D51: algemeen | E51: Goed zaken doen | G51: 4 | H51: 108 | I51: 27 | J51: wo
A52: 50 | B52: Agrifirm | C52: Evert Hofman & Abemec | D52: algemeen | E52: Toekomst Techniek toepassing GBM | G52: 4 | H52: 108 | I52: 27 | J52: wo
A53: 51 | B53: Agrifirm & UPL | C53: Joris Roskam & Marcel van Doorne | D53: bieten | E53: GEWASKRACHT REEF technische introductie | G53: 4 | H53: 108 | I53: 27 | J53: wo
A54: 52 | B54: Agrifirm | C54: Gewasbescherming in een notedop | D54: algemeen | E54: introductie voor Abemec | G54: 1 | H54: 25 | I54: 25 | J54: wo
...

Sheet Keuze per deelnemer
A1: Id | B1: Naam | C1: 1 | D1: 2 | E1: 3 | F1: 4 | G1: 5 | H1: 6 | I1: 7 | J1: 8 | K1: 9 | L1: 10 | M1: 11 | N1: 12 | O1: 13 | P1: 14 | Q1: 15 | R1: 16 | S1: 17 | T1: 18 | U1: 19 | V1: 20 | W1: 21
A2: 1 | B2: Jan Derks Kloosterboer | C2: 45 | D2: 41 | E2: 37 | F2: 33 | G2: 34 | H2: 31 | I2: 30 | J2: 28 | K2: 27 | L2: 5 | M2: 11 | N2: 14 | O2: 17 | R2: 46 | S2: 47 | T2: 49 | U2: 50 | V2: 51 | W2: 48
A3: 2 | B3: Rens Hupkes | C3: 4 | D3: 2 | E3: 5 | F3: 12 | G3: 20 | H3: 26 | I3: 27 | J3: 39 | K3: 45 | L3: 42 | M3: 10 | N3: 11 | O3: 16 | R3: 46 | S3: 47 | T3: 49 | U3: 50 | V3: 51 | W3: 48
A4: 3 | B4: Maurice van den Boom | C4: 45 | D4: 42 | E4: 39 | F4: 36 | G4: 34 | H4: 27 | I4: 23 | J4: 20 | K4: 18 | L4: 14 | M4: 4 | N4: 25 | O4: 31 | P4: 33 | Q4: 38 | R4: 46 | S4: 47 | T4: 49 | U4: 50 | V4: 51 | W4: 48
A5: 4 | B5: Jorrit Krom | C5: 5 | D5: 14 | E5: 15 | F5: 16 | G5: 18 | H5: 20 | I5: 22 | J5: 24 | K5: 27 | L5: 29 | M5: 31 | N5: 32 | O5: 33 | P5: 34 | Q5: 38 | R5: 46 | S5: 47 | T5: 49 | U5: 50 | V5: 51 | W5: 48
A6: 5 | B6: Teun van de Wassenberg | C6: 4 | D6: 7 | E6: 10 | F6: 26 | G6: 18 | H6: 28 | I6: 39 | J6: 42 | K6: 45 | L6: 12 | M6: 16 | N6: 2 | O6: 25 | P6: 33 | Q6: 36 | R6: 46 | S6: 47 | T6: 49 | U6: 50 | V6: 51 | W6: 48
A7: 6 | B7: Ronald Hendriksen | C7: 10 | D7: 14 | E7: 16 | F7: 20 | G7: 23 | H7: 31 | I7: 30 | J7: 32 | K7: 33 | L7: 34 | M7: 35 | N7: 38 | O7: 39 | P7: 42 | Q7: 5 | R7: 46 | S7: 47 | T7: 49 | U7: 50 | V7: 51 | W7: 48
A8: 7 | B8: Ton Stoorvogel | C8: 14 | D8: 23 | E8: 24 | F8: 29 | G8: 30 | H8: 31 | I8: 32 | J8: 33 | K8: 34 | L8: 36 | M8: 35 | N8: 37 | O8: 38 | P8: 40 | Q8: 22 | R8: 46 | S8: 47 | T8: 49 | U8: 50 | V8: 51 | W8: 48
A9: 8 | B9: Raymond Sweertman | C9: 5 | D9: 18 | E9: 42 | F9: 6 | G9: 12 | H9: 20 | I9: 23 | J9: 34 | K9: 38 | L9: 28 | M9: 1 | N9: 7 | O9: 45 | P9: 22 | Q9: 30 | R9: 46 | S9: 47 | T9: 49 | U9: 50 | V9: 51 | W9: 48
A10: 9 | B10: Arnold Kremer | C10: 4 | D10: 5 | E10: 11 | F10: 12 | G10: 17 | H10: 23 | I10: 25 | J10: 29 | K10: 30 | L10: 36 | M10: 45 | N10: 2 | O10: 14 | P10: 16 | Q10: 38 | R10: 46 | S10: 47 | T10: 49 | U10: 50 | V10: 51 | W10: 48
A11: 10 | B11: Linette Holsappel - van Staalduinen | C11: 5 | D11: 6 | E11: 10 | F11: 2 | G11: 11 | H11: 15 | I11: 20 | J11: 23 | K11: 30 | L11: 35 | M11: 36 | N11: 43 | O11: 14 | P11: 22 | Q11: 26 | R11: 46 | S11: 47 | T11: 49 | U11: 50 | V11: 51 | W11: 48
A12: 11 | B12: Kor Tempel | C12: 2 | D12: 5 | E12: 15 | F12: 16 | G12: 17 | H12: 18 | I12: 19 | J12: 43 | K12: 38 | L12: 23 | M12: 34 | N12: 28 | O12: 7 | P12: 12 | Q12: 14 | R12: 46 | S12: 47 | T12: 49 | U12: 50 | V12: 51 | W12: 48
A13: 12 | B13: Lieuwe Elzinga | C13: 5 | D13: 11 | E13: 19 | F13: 22 | G13: 23 | H13: 24 | I13: 27 | J13: 30 | K13: 34 | L13: 37 | M13: 15 | N13: 40 | O13: 45 | P13: 33 | Q13: 32 | R13: 46 | S13: 47 | T13: 49 | U13: 50 | V13: 51 | W13: 48
A14: 13 | B14: Harry Sanders | C14: 45 | D14: 44 | E14: 43 | F14: 12 | G14: 15 | H14: 18 | I14: 19 | J14: 26 | K14: 27 | L14: 29 | M14: 39 | N14: 4 | O14: 36 | R14: 46 | S14: 47 | T14: 49 | U14: 50 | V14: 51 | W14: 48
A15: 14 | B15: Tom de Visser | C15: 5 | D15: 10 | E15: 11 | F15: 15 | G15: 20 | H15: 25 | I15: 30 | J15: 42 | K15: 35 | L15: 38 | M15: 45 | N15: 2 | O15: 3 | P15: 18 | R15: 46 | S15: 47 | T15: 49 | U15: 50 | V15: 51 | W15: 48
A16: 15 | B16: Cok van der Maarl | C16: 45 | D16: 43 | E16: 42 | F16: 2 | G16: 3 | H16: 10 | I16: 16 | J16: 20 | K16: 25 | L16: 27 | M16: 35 | N16: 12 | O16: 18 | P16: 28 | R16: 46 | S16: 47 | T16: 49 | U16: 50 | V16: 51 | W16: 48
A17: 16 | B17: Erik Dilling | C17: 23 | D17: 45 | E17: 20 | F17: 19 | G17: 35 | H17: 34 | I17: 41 | J17: 42 | K17: 43 | L17: 18 | M17: 5 | N17: 32 | O17: 28 | P17: 30 | Q17: 29 | R17: 46 | S17: 47 | T17: 49 | U17: 50 | V17: 51 | W17: 48
A18: 17 | B18: Ries van den Boogert | C18: 2 | D18: 4 | E18: 5 | F18: 10 | G18: 11 | H18: 12 | I18: 14 | J18: 19 | K18: 20 | L18: 25 | M18: 33 | N18: 35 | O18: 36 | P18: 41 | Q18: 38 | R18: 46 | S18: 47 | T18: 49 | U18: 50 | V18: 51 | W18: 48
A19: 18 | B19: Stijn Jeuken | C19: 5 | D19: 7 | E19: 12 | F19: 20 | G19: 23 | H19: 27 | I19: 39 | J19: 25 | K19: 17 | L19: 14 | M19: 1 | N19: 4 | O19: 45 | P19: 30 | R19: 46 | S19: 47 | T19: 49 | U19: 50 | V19: 51 | W19: 48
A20: 19 | B20: Bram Schilder | C20: 5 | D20: 6 | E20: 11 | F20: 12 | G20: 16 | H20: 20 | I20: 22 | J20: 27 | K20: 30 | L20: 31 | M20: 32 | N20: 33 | O20: 35 | P20: 42 | Q20: 45 | R20: 46 | S20: 47 | T20: 49 | U20: 50 | V20: 51 | W20: 48
A21: 20 | B21: Wilko Wingelaar | C21: 45 | D21: 42 | E21: 39 | F21: 28 | G21: 27 | H21: 26 | I21: 3 | J21: 5 | K21: 10 | L21: 12 | M21: 15 | N21: 17 | O21: 16 | R21: 46 | S21: 47 | T21: 49 | U21: 50 | V21: 51 | W21: 48
A22: 21 | B22: René Huls | C22: 4 | D22: 5 | E22: 6 | F22: 42 | G22: 36 | H22: 31 | I22: 30 | J22: 27 | K22: 24 | L22: 22 | M22: 20 | N22: 38 | O22: 11 | R22: 46 | S22: 47 | T22: 49 | U22: 50 | V22: 51 | W22: 48
A23: 22 | B23: Sander Hofhuis | C23: 5 | D23: 45 | E23: 43 | F23: 42 | G23: 41 | H23: 2 | I23: 4 | J23: 12 | K23: 23 | L23: 20 | M23: 7 | N23: 10 | O23: 18 | P23: 30 | Q23: 28 | R23: 46 | S23: 47 | T23: 49 | U23: 50 | V23: 51 | W23: 48
A24: 23 | B24: Kees Overheul | C24: 4 | D24: 5 | E24: 11 | F24: 12 | G24: 14 | H24: 30 | I24: 34 | J24: 36 | K24: 41 | L24: 45 | M24: 40 | N24: 38 | O24: 24 | P24: 23 | Q24: 22 | R24: 46 | S24: 47 | T24: 49 | U24: 50 | V24: 51 | W24: 48
A25: 24 | B25: Fokko Prins | C25: 4 | D25: 11 | E25: 12 | F25: 15 | G25: 16 | H25: 20 | I25: 22 | J25: 23 | K25: 24 | L25: 26 | M25: 32 | N25: 36 | O25: 38 | P25: 43 | Q25: 45 | R25: 46 | S25: 47 | T25: 49 | U25: 50 | V25: 51 | W25: 48
A26: 25 | B26: Mark Schepers | C26: 2 | D26: 5 | E26: 6 | F26: 10 | G26: 12 | H26: 18 | I26: 20 | J26: 23 | K26: 26 | L26: 27 | M26: 39 | N26: 7 | O26: 42 | P26: 16 | R26: 46 | S26: 47 | T26: 49 | U26: 50 | V26: 51 | W26: 48
A27: 26 | B27: Lex Broersen | C27: 1 | D27: 2 | E27: 45 | F27: 43 | G27: 35 | H27: 31 | I27: 34 | J27: 10 | K27: 14 | L27: 15 | M27: 20 | N27: 22 | O27: 23 | P27: 4 | R27: 46 | S27: 47 | T27: 49 | U27: 50 | V27: 51 | W27: 48
A28: 27 | B28: Marcel Schut | C28: 3 | D28: 2 | E28: 5 | F28: 10 | G28: 11 | H28: 14 | I28: 16 | J28: 22 | K28: 34 | L28: 37 | M28: 38 | N28: 39 | O28: 45 | R28: 46 | S28: 47 | T28: 49 | U28: 50 | V28: 51 | W28: 48
A29: 28 | B29: Joep Maas | C29: 1 | D29: 4 | E29: 5 | F29: 7 | G29: 14 | H29: 15 | I29: 16 | J29: 20 | K29: 23 | L29: 27 | M29: 30 | N29: 35 | O29: 39 | P29: 45 | R29: 46 | S29: 47 | T29: 49 | U29: 50 | V29: 51 | W29: 48
A30: 29 | B30: Johan Ottens | C30: 3 | D30: 4 | E30: 5 | F30: 12 | G30: 15 | H30: 18 | I30: 27 | J30: 24 | K30: 38 | L30: 43 | M30: 45 | N30: 36 | O30: 26 | P30: 34 | R30: 46 | S30: 47 | T30: 49 | U30: 50 | V30: 51 | W30: 48
A31: 30 | B31: Nanda ter Huurne | C31: 4 | D31: 5 | E31: 3 | F31: 10 | G31: 17 | H31: 23 | I31: 27 | J31: 29 | K31: 32 | L31: 34 | M31: 38 | N31: 45 | O31: 43 | P31: 41 | Q31: 39 | R31: 46 | S31: 47 | T31: 49 | U31: 50 | V31: 51 | W31: 48
A32: 31 | B32: Martin van Rijn | C32: 3 | D32: 5 | E32: 10 | F32: 12 | G32: 15 | H32: 17 | I32: 20 | J32: 22 | K32: 23 | L32: 24 | M32: 30 | N32: 34 | O32: 42 | P32: 45 | Q32: 35 | R32: 46 | S32: 47 | T32: 49 | U32: 50 | V32: 51 | W32: 48
A33: 32 | B33: Henk-Jan van der Struik | C33: 2 | D33: 4 | E33: 5 | F33: 18 | G33: 41 | H33: 42 | I33: 45 | J33: 6 | K33: 7 | L33: 10 | M33: 16 | N33: 26 | O33: 12 | P33: 27 | R33: 46 | S33: 47 | T33: 49 | U33: 50 | V33: 51 | W33: 48
A34: 33 | B34: Christiaan Bootsma | C34: 3 | D34: 16 | E34: 20 | F34: 23 | G34: 22 | H34: 27 | I34: 31 | J34: 32 | K34: 34 | L34: 40 | M34: 45 | R34: 46 | S34: 47 | T34: 49 | U34: 50 | V34: 51 | W34: 48
A35: 34 | B35: Andre Groot Nibbelink | C35: 12 | D35: 14 | E35: 10 | F35: 2 | G35: 23 | H35: 27 | I35: 34 | J35: 36 | K35: 43 | L35: 45 | M35: 40 | N35: 35 | O35: 31 | P35: 4 | Q35: 15 | R35: 46 | S35: 47 | T35: 49 | U35: 50 | V35: 51 | W35: 48
A36: 35 | B36: Liza Lievens | C36: 1 | D36: 3 | E36: 5 | F36: 40 | G36: 39 | H36: 38 | I36: 35 | J36: 34 | K36: 29 | L36: 28 | M36: 27 | N36: 7 | O36: 14 | P36: 22 | R36: 46 | S36: 47 | T36: 49 | U36: 50 | V36: 51 | W36: 48
A37: 36 | B37: Anke van Oorschot | C37: 5 | D37: 12 | E37: 19 | F37: 28 | G37: 30 | H37: 38 | I37: 42 | J37: 45 | K37: 39 | L37: 36 | M37: 33 | N37: 27 | O37: 26 | P37: 20 | Q37: 15 | R37: 46 | S37: 47 | T37: 49 | U37: 50 | V37: 51 | W37: 48
A38: 37 | B38: Peter Hulst | C38: 5 | D38: 10 | E38: 11 | F38: 12 | G38: 14 | H38: 22 | I38: 23 | J38: 27 | K38: 28 | L38: 31 | M38: 34 | N38: 36 | O38: 39 | P38: 42 | Q38: 45 | R38: 46 | S38: 47 | T38: 49 | U38: 50 | V38: 51 | W38: 48
A39: 38 | B39: Theo Brookman | C39: 2 | D39: 3 | E39: 10 | F39: 11 | G39: 20 | H39: 36 | I39: 42 | J39: 45 | K39: 44 | L39: 38 | M39: 30 | N39: 25 | O39: 22 | P39: 15 | Q39: 16 | R39: 46 | S39: 47 | T39: 49 | U39: 50 | V39: 51 | W39: 48
A40: 39 | B40: Patrick Lamers | C40: 3 | D40: 1 | E40: 5 | F40: 10 | G40: 17 | H40: 19 | I40: 20 | J40: 25 | K40: 26 | L40: 29 | M40: 30 | N40: 38 | O40: 42 | P40: 6 | R40: 46 | S40: 47 | T40: 49 | U40: 50 | V40: 51 | W40: 48
...

Sheet Ruimte per zaal
A1: Dag 1
A2: Gouden Leeuw 2 | B2: 45
A3: Gouden Leeuw 3 | B3: 35
A4: Kinderdijk | B4: 27
A5: Princeville | B5: 27
A6: Haagse Schouw | B6: 27
A7: De Witte | B7: 27
A10: Dag 2
A11: Gouden Leeuw 2 | B11: 45
A12: Gouden Leeuw 3 | B12: 35
A13: Princeville | B13: 27
A14: Haagse Schouw | B14: 27
A15: De Witte | B15: 27
A17: *Verplichte lezingen dag 1 (47, 49, 50 en 51) maximaal 32 personen ipv 27
